<?xml version="1.0" encoding="utf-8"?>
<!-- This URDF was automatically created by SolidWorks to URDF Exporter! Originally created by Stephen Brawner (brawner@gmail.com) 
     Commit Version: 1.5.1-0-g916b5db  Build Version: 1.5.7152.31018
     For more information, please see http://wiki.ros.org/sw_urdf_exporter -->
<robot
  name="arm_robotv2conti">
  <link
    name="base_link">
    <inertial>
      <origin
        xyz="3.8858E-15 5.5511E-17 0.03937"
        rpy="0 0 0" />
      <mass
        value="5.7683" />
      <inertia
        ixx="0.035857"
        ixy="-1.0178E-17"
        ixz="-3.3641E-15"
        iyy="0.035857"
        iyz="4.3032E-18"
        izz="0.065487" />
    </inertial>
    <visual>
      <origin
        xyz="0 0 0"
        rpy="0 0 0" />
      <geometry>
        <mesh
          filename="package://arm_robotv2conti/meshes/base_link.STL" />
      </geometry>
      <material
        name="">
        <color
          rgba="0.79216 0.81961 0.93333 1" />
      </material>
    </visual>
    <collision>
      <origin
        xyz="0 0 0"
        rpy="0 0 0" />
      <geometry>
        <mesh
          filename="package://arm_robotv2conti/meshes/base_link.STL" />
      </geometry>
    </collision>
  </link>
  <link
    name="link1">
    <inertial>
      <origin
        xyz="-6.4922E-05 0.10116 -0.036236"
        rpy="0 0 0" />
      <mass
        value="2.1858" />
      <inertia
        ixx="0.024142"
        ixy="1.663E-05"
        ixz="-1.003E-05"
        iyy="0.0099036"
        iyz="0.0078407"
        izz="0.018136" />
    </inertial>
    <visual>
      <origin
        xyz="0 0 0"
        rpy="0 0 0" />
      <geometry>
        <mesh
          filename="package://arm_robotv2conti/meshes/link1.STL" />
      </geometry>
      <material
        name="">
        <color
          rgba="0.79216 0.81961 0.93333 1" />
      </material>
    </visual>
    <collision>
      <origin
        xyz="0 0 0"
        rpy="0 0 0" />
      <geometry>
        <mesh
          filename="package://arm_robotv2conti/meshes/link1.STL" />
      </geometry>
    </collision>
  </link>
  <joint
    name="joint1"
    type="continuous">
    <origin
      xyz="0 0 0.082"
      rpy="1.5708 0 0" />
    <parent
      link="base_link" />
    <child
      link="link1" />
    <axis
      xyz="0 1 0" />
    <limit
      lower="0"
      upper="0"
      effort="0"
      velocity="0" />
  </joint>
  <link
    name="link2">
    <inertial>
      <origin
        xyz="-0.14798 -1.6931E-15 -0.036651"
        rpy="0 0 0" />
      <mass
        value="0.91584" />
      <inertia
        ixx="0.00060259"
        ixy="-2.8459E-17"
        ixz="2.1008E-05"
        iyy="0.016248"
        iyz="-3.8195E-19"
        izz="0.016691" />
    </inertial>
    <visual>
      <origin
        xyz="0 0 0"
        rpy="0 0 0" />
      <geometry>
        <mesh
          filename="package://arm_robotv2conti/meshes/link2.STL" />
      </geometry>
      <material
        name="">
        <color
          rgba="0.79216 0.81961 0.93333 1" />
      </material>
    </visual>
    <collision>
      <origin
        xyz="0 0 0"
        rpy="0 0 0" />
      <geometry>
        <mesh
          filename="package://arm_robotv2conti/meshes/link2.STL" />
      </geometry>
    </collision>
  </link>
  <joint
    name="joint2"
    type="continuous">
    <origin
      xyz="0 0.2189 -0.10757"
      rpy="1.5708 -0.042831 -1.5708" />
    <parent
      link="link1" />
    <child
      link="link2" />
    <axis
      xyz="0 0 1" />
    <limit
      lower="0"
      upper="0"
      effort="0"
      velocity="0" />
  </joint>
  <link
    name="link3">
    <inertial>
      <origin
        xyz="0.173667313371488 0.0341123307044733 -0.0226589709707138"
        rpy="0 0 0" />
      <mass
        value="2.88874963505171" />
      <inertia
        ixx="0.00390076765921893"
        ixy="-0.00169954421697166"
        ixz="-7.98282966539592E-05"
        iyy="0.0604294396867143"
        iyz="-1.56821949529981E-05"
        izz="0.0612301290971159" />
    </inertial>
    <visual>
      <origin
        xyz="0 0 0"
        rpy="0 0 0" />
      <geometry>
        <mesh
          filename="package://arm_robotv2conti/meshes/link3.STL" />
      </geometry>
      <material
        name="">
        <color
          rgba="0.792156862745098 0.819607843137255 0.933333333333333 1" />
      </material>
    </visual>
    <collision>
      <origin
        xyz="0 0 0"
        rpy="0 0 0" />
      <geometry>
        <mesh
          filename="package://arm_robotv2conti/meshes/link3.STL" />
      </geometry>
    </collision>
  </link>
  <joint
    name="joint3"
    type="continuous">
    <origin
      xyz="-0.35 0 0"
      rpy="-3.1416 0 -1.6136" />
    <parent
      link="link2" />
    <child
      link="link3" />
    <axis
      xyz="0 0 -1" />
    <limit
      lower="0"
      upper="0"
      effort="0"
      velocity="0" />
  </joint>
  <link
    name="link4">
    <inertial>
      <origin
        xyz="0.0614276434779976 -2.28523452383556E-08 -0.0229962167228982"
        rpy="0 0 0" />
      <mass
        value="0.434843681196637" />
      <inertia
        ixx="0.0003128369849016"
        ixy="-6.03364723206629E-11"
        ixz="1.01085582260247E-07"
        iyy="0.000617098399563288"
        iyz="1.5950270320187E-10"
        izz="0.00060932541889194" />
    </inertial>
    <visual>
      <origin
        xyz="0 0 0"
        rpy="0 0 0" />
      <geometry>
        <mesh
          filename="package://arm_robotv2conti/meshes/link4.STL" />
      </geometry>
      <material
        name="">
        <color
          rgba="0.792156862745098 0.819607843137255 0.933333333333333 1" />
      </material>
    </visual>
    <collision>
      <origin
        xyz="0 0 0"
        rpy="0 0 0" />
      <geometry>
        <mesh
          filename="package://arm_robotv2conti/meshes/link4.STL" />
      </geometry>
    </collision>
  </link>
  <joint
    name="joint4"
    type="continuous">
    <origin
      xyz="0.391 0.0375 0"
      rpy="0 0 0" />
    <parent
      link="link3" />
    <child
      link="link4" />
    <axis
      xyz="0 0 1" />
    <limit
      lower="0"
      upper="0"
      effort="0"
      velocity="0" />
  </joint>
</robot>